Workbook

Sheet Summary
A1: indiarfidshop.com – Title Tag & On-Page SEO Audit
A2: Audit date: 7 Oct 2026 · Source: live pages fetched from indiarfidshop.com (all 49 sitemap URLs)
A4: Headline numbers
A5: Pages audited | B5: =COUNTA('All Pages'!C2:C50) -> 49
A6: Pages with missing title | B6: =COUNTBLANK('All Pages'!D2:D50) -> 0
A7: Pages needing a fix | B7: =COUNTIF('All Pages'!K2:K50,"Needs fix") -> 48
A8: Pages with brand twice | B8: =COUNTIF('All Pages'!F2:F50,">1") -> 15
A9: Pages with duplicate titles | B9: =COUNTIF('All Pages'!H2:H50,"Duplicate") -> 14
A10: Pages with titles over 60 chars | B10: =COUNTIF('All Pages'!G2:G50,"Too long") -> 16
A11: Total issues logged | B11: =COUNTA(Issues!A2:A74) -> 73
A12: Issues still open | B12: =COUNTIFS(Issues!M2:M74,"<>Fixed",Issues!M2:M74,"<>Verified") -> 73
A14: Issues by problem | B14: Total | C14: High | D14: Medium | E14: Low
A15: Duplicate brand in title | B15: =COUNTIF(Issues!$F$2:$F$74,A15) -> 15 | C15: =COUNTIFS(Issues!$F$2:$F$74,$A15,Issues!$B$2:$B$74,"High") -> 13 | D15: =COUNTIFS(Issues!$F$2:$F$74,$A15,Issues!$B$2:$B$74,"Medium") -> 2 | E15: =COUNTIFS(Issues!$F$2:$F$74,$A15,Issues!$B$2:$B$74,"Low") -> 0
A16: Generic title – no keywords | B16: =COUNTIF(Issues!$F$2:$F$74,A16) -> 5 | C16: =COUNTIFS(Issues!$F$2:$F$74,$A16,Issues!$B$2:$B$74,"High") -> 1 | D16: =COUNTIFS(Issues!$F$2:$F$74,$A16,Issues!$B$2:$B$74,"Medium") -> 1 | E16: =COUNTIFS(Issues!$F$2:$F$74,$A16,Issues!$B$2:$B$74,"Low") -> 3
A17: Duplicate title across category pages | B17: =COUNTIF(Issues!$F$2:$F$74,A17) -> 13 | C17: =COUNTIFS(Issues!$F$2:$F$74,$A17,Issues!$B$2:$B$74,"High") -> 13 | D17: =COUNTIFS(Issues!$F$2:$F$74,$A17,Issues!$B$2:$B$74,"Medium") -> 0 | E17: =COUNTIFS(Issues!$F$2:$F$74,$A17,Issues!$B$2:$B$74,"Low") -> 0
A18: Title is only model name – no keywords | B18: =COUNTIF(Issues!$F$2:$F$74,A18) -> 4 | C18: =COUNTIFS(Issues!$F$2:$F$74,$A18,Issues!$B$2:$B$74,"High") -> 4 | D18: =COUNTIFS(Issues!$F$2:$F$74,$A18,Issues!$B$2:$B$74,"Medium") -> 0 | E18: =COUNTIFS(Issues!$F$2:$F$74,$A18,Issues!$B$2:$B$74,"Low") -> 0
A19: Spammy / question-style title | B19: =COUNTIF(Issues!$F$2:$F$74,A19) -> 1 | C19: =COUNTIFS(Issues!$F$2:$F$74,$A19,Issues!$B$2:$B$74,"High") -> 1 | D19: =COUNTIFS(Issues!$F$2:$F$74,$A19,Issues!$B$2:$B$74,"Medium") -> 0 | E19: =COUNTIFS(Issues!$F$2:$F$74,$A19,Issues!$B$2:$B$74,"Low") -> 0
A20: Model number missing from title | B20: =COUNTIF(Issues!$F$2:$F$74,A20) -> 1 | C20: =COUNTIFS(Issues!$F$2:$F$74,$A20,Issues!$B$2:$B$74,"High") -> 1 | D20: =COUNTIFS(Issues!$F$2:$F$74,$A20,Issues!$B$2:$B$74,"Medium") -> 0 | E20: =COUNTIFS(Issues!$F$2:$F$74,$A20,Issues!$B$2:$B$74,"Low") -> 0
A21: Canonical tag missing | B21: =COUNTIF(Issues!$F$2:$F$74,A21) -> 1 | C21: =COUNTIFS(Issues!$F$2:$F$74,$A21,Issues!$B$2:$B$74,"High") -> 1 | D21: =COUNTIFS(Issues!$F$2:$F$74,$A21,Issues!$B$2:$B$74,"Medium") -> 0 | E21: =COUNTIFS(Issues!$F$2:$F$74,$A21,Issues!$B$2:$B$74,"Low") -> 0
A22: Typo in category URL | B22: =COUNTIF(Issues!$F$2:$F$74,A22) -> 2 | C22: =COUNTIFS(Issues!$F$2:$F$74,$A22,Issues!$B$2:$B$74,"High") -> 0 | D22: =COUNTIFS(Issues!$F$2:$F$74,$A22,Issues!$B$2:$B$74,"Medium") -> 2 | E22: =COUNTIFS(Issues!$F$2:$F$74,$A22,Issues!$B$2:$B$74,"Low") -> 0
A23: H1 contains '|' / brand text | B23: =COUNTIF(Issues!$F$2:$F$74,A23) -> 4 | C23: =COUNTIFS(Issues!$F$2:$F$74,$A23,Issues!$B$2:$B$74,"High") -> 0 | D23: =COUNTIFS(Issues!$F$2:$F$74,$A23,Issues!$B$2:$B$74,"Medium") -> 4 | E23: =COUNTIFS(Issues!$F$2:$F$74,$A23,Issues!$B$2:$B$74,"Low") -> 0
A24: Weak meta description | B24: =COUNTIF(Issues!$F$2:$F$74,A24) -> 6 | C24: =COUNTIFS(Issues!$F$2:$F$74,$A24,Issues!$B$2:$B$74,"High") -> 0 | D24: =COUNTIFS(Issues!$F$2:$F$74,$A24,Issues!$B$2:$B$74,"Medium") -> 6 | E24: =COUNTIFS(Issues!$F$2:$F$74,$A24,Issues!$B$2:$B$74,"Low") -> 0
A25: Generic og:title (social share title) | B25: =COUNTIF(Issues!$F$2:$F$74,A25) -> 1 | C25: =COUNTIFS(Issues!$F$2:$F$74,$A25,Issues!$B$2:$B$74,"High") -> 0 | D25: =COUNTIFS(Issues!$F$2:$F$74,$A25,Issues!$B$2:$B$74,"Medium") -> 1 | E25: =COUNTIFS(Issues!$F$2:$F$74,$A25,Issues!$B$2:$B$74,"Low") -> 0
A26: Generic twitter:title / twitter:description | B26: =COUNTIF(Issues!$F$2:$F$74,A26) -> 1 | C26: =COUNTIFS(Issues!$F$2:$F$74,$A26,Issues!$B$2:$B$74,"High") -> 0 | D26: =COUNTIFS(Issues!$F$2:$F$74,$A26,Issues!$B$2:$B$74,"Medium") -> 1 | E26: =COUNTIFS(Issues!$F$2:$F$74,$A26,Issues!$B$2:$B$74,"Low") -> 0
... A31: H1 does not match title | B31: =COUNTIF(Issues!$F$2:$F$74,A31) -> 2 | C31: =COUNTIFS(Issues!$F$2:$F$74,$A31,Issues!$B$2:$B$74,"High") -> 0 | D31: =COUNTIFS(Issues!$F$2:$F$74,$A31,Issues!$B$2:$B$74,"Medium") -> 0 | E31: =COUNTIFS(Issues!$F$2:$F$74,$A31,Issues!$B$2:$B$74,"Low") -> 2
A32: Total | B32: =SUM(B15:B31) -> 73 | C32: =SUM(C15:C31) -> 34 | D32: =SUM(D15:D31) -> 19 | E32: =SUM(E15:E31) -> 20
A34: How to use this workbook
A35: • Issues: one row per problem per page, sorted High → Low. Work top-down.
A36: • Edit only the yellow columns (Status, Owner, Notes). Status: Open / In Progress / Fixed / Verified.
A37: • 'Suggested Value' = what to type in your admin panel. Titles are entered WITHOUT '| Virtualsphere' – the site adds it (see Final Title column).
A38: • All Pages: every sitemap URL with its live title and automatic checks (length, brand count, duplicates).
A39: • Code Fixes: the Next.js changes that fix most issues in one deploy (fixes 1, 2 and 4 cover ~30 pages).
A40: • No page is missing a title tag – the problems are duplicates, missing keywords and length.

Sheet Issues
A1: ID | B1: Priority | C1: Page Type | D1: Page Name | E1: Page URL | F1: Problem | G1: Current Value | H1: Problem Details | I1: Fix Steps | J1: Suggested Value (enter in admin) | K1: Final Title in Google | L1: Final Title Length | M1: Status | N1: Owner | O1: Notes
A2: T001 | B2: High | C2: Home | D2: Homepage | E2: https://indiarfidshop.com/ | F2: Duplicate brand in title | G2: Virtualsphere — Enterprise RFID Solutions | Virtualsphere | H2: 'Virtualsphere' appears twice. Google sees repeated words; wastes title space. | I2: 1) Set this page's metadata title to the Suggested Title only (no brand) – the layout template adds ' | Virtualsphere'. 2) For the homepage use title: { absolute: '<full title>' } so the template is not added twice. 3) Deploy and confirm the brand appears once in page source. | J2: RFID Readers, Tags & Antennas in India | Virtualsphere | K2: =J2 -> RFID Readers, Tags & Antennas in India | Virtualsphere | L2: =IF(K2="","",LEN(K2)) -> 54 | M2: Open
A3: T002 | B3: High | C3: Home | D3: Homepage | E3: https://indiarfidshop.com/ | F3: Generic title – no keywords | G3: Virtualsphere — Enterprise RFID Solutions | Virtualsphere | H3: Homepage title has no product keywords (RFID reader, tags, antenna) and no 'India'; homepage is your strongest page for ranking. | I3: 1) Set a page-specific metadata title (Suggested Title) in this page's page.tsx. 2) Include what the page offers + a keyword (RFID readers, tags, India). 3) Deploy and verify in page source. | J3: RFID Readers, Tags & Antennas in India | Virtualsphere | K3: =J3 -> RFID Readers, Tags & Antennas in India | Virtualsphere | L3: =IF(K3="","",LEN(K3)) -> 54 | M3: Open
A4: T003 | B4: High | C4: Category | D4: Barcode Printers | E4: https://indiarfidshop.com/products?category=barcode-printers | F4: Duplicate title across category pages | G4: Products | Virtualsphere | H4: All 13 category pages share the title 'Products | Virtualsphere' (and the same meta description). Google treats them as duplicates and none ranks for 'Barcode Printers'. Verified live on handheld-reader and raid-tags; same template for all categories. | I4: 1) In app/products/page.tsx add generateMetadata({ searchParams }) that reads ?category=, looks up the category name and returns title: category ? <Suggested Title> : 'Buy RFID Readers, Tags & Antennas Online'. 2) Also return a matching meta description (use the category description) and canonical /products?category=<slug>. 3) Deploy and check page source for each category URL. | J4: Barcode Printers | K4: =J4&" | Virtualsphere" -> Barcode Printers | Virtualsphere | L4: =IF(K4="","",LEN(K4)) -> 32 | M4: Open
A5: T004 | B5: High | C5: Category | D5: UHF Integrated Reader | E5: https://indiarfidshop.com/products?category=integrated-reader | F5: Duplicate title across category pages | G5: Products | Virtualsphere | H5: All 13 category pages share the title 'Products | Virtualsphere' (and the same meta description). Google treats them as duplicates and none ranks for 'UHF Integrated Reader'. Verified live on handheld-reader and raid-tags; same template for all categories. | I5: 1) In app/products/page.tsx add generateMetadata({ searchParams }) that reads ?category=, looks up the category name and returns title: category ? <Suggested Title> : 'Buy RFID Readers, Tags & Antennas Online'. 2) Also return a matching meta description (use the category description) and canonical /products?category=<slug>. 3) Deploy and check page source for each category URL. | J5: UHF Integrated RFID Readers | K5: =J5&" | Virtualsphere" -> UHF Integrated RFID Readers | Virtualsphere | L5: =IF(K5="","",LEN(K5)) -> 43 | M5: Open
A6: T005 | B6: High | C6: Category | D6: Four Port UHF Reader | E6: https://indiarfidshop.com/products?category=four-port-reader | F6: Duplicate title across category pages | G6: Products | Virtualsphere | H6: All 13 category pages share the title 'Products | Virtualsphere' (and the same meta description). Google treats them as duplicates and none ranks for 'Four Port UHF Reader'. Verified live on handheld-reader and raid-tags; same template for all categories. | I6: 1) In app/products/page.tsx add generateMetadata({ searchParams }) that reads ?category=, looks up the category name and returns title: category ? <Suggested Title> : 'Buy RFID Readers, Tags & Antennas Online'. 2) Also return a matching meta description (use the category description) and canonical /products?category=<slug>. 3) Deploy and check page source for each category URL. | J6: 4-Port UHF RFID Fixed Readers | K6: =J6&" | Virtualsphere" -> 4-Port UHF RFID Fixed Readers | Virtualsphere | L6: =IF(K6="","",LEN(K6)) -> 45 | M6: Open
A7: T006 | B7: High | C7: Category | D7: RFID Tags | E7: https://indiarfidshop.com/products?category=raid-tags | F7: Duplicate title across category pages | G7: Products | Virtualsphere | H7: All 13 category pages share the title 'Products | Virtualsphere' (and the same meta description). Google treats them as duplicates and none ranks for 'RFID Tags'. Verified live on handheld-reader and raid-tags; same template for all categories. | I7: 1) In app/products/page.tsx add generateMetadata({ searchParams }) that reads ?category=, looks up the category name and returns title: category ? <Suggested Title> : 'Buy RFID Readers, Tags & Antennas Online'. 2) Also return a matching meta description (use the category description) and canonical /products?category=<slug>. 3) Deploy and check page source for each category URL. | J7: RFID Tags – UHF, HF & On-Metal | K7: =J7&" | Virtualsphere" -> RFID Tags – UHF, HF & On-Metal | Virtualsphere | L7: =IF(K7="","",LEN(K7)) -> 46 | M7: Open
A8: T007 | B8: High | C8: Category | D8: RFID UHF Labels | E8: https://indiarfidshop.com/products?category=Rfid-uhf-label-tags | F8: Duplicate title across category pages | G8: Products | Virtualsphere | H8: All 13 category pages share the title 'Products | Virtualsphere' (and the same meta description). Google treats them as duplicates and none ranks for 'RFID UHF Labels'. Verified live on handheld-reader and raid-tags; same template for all categories. | I8: 1) In app/products/page.tsx add generateMetadata({ searchParams }) that reads ?category=, looks up the category name and returns title: category ? <Suggested Title> : 'Buy RFID Readers, Tags & Antennas Online'. 2) Also return a matching meta description (use the category description) and canonical /products?category=<slug>. 3) Deploy and check page source for each category URL. | J8: UHF RFID Labels | K8: =J8&" | Virtualsphere" -> UHF RFID Labels | Virtualsphere | L8: =IF(K8="","",LEN(K8)) -> 31 | M8: Open
A9: T008 | B9: High | C9: Category | D9: RFID Laundry Tags | E9: https://indiarfidshop.com/products?category=rfid-laundary-tags | F9: Duplicate title across category pages | G9: Products | Virtualsphere | H9: All 13 category pages share the title 'Products | Virtualsphere' (and the same meta description). Google treats them as duplicates and none ranks for 'RFID Laundry Tags'. Verified live on handheld-reader and raid-tags; same template for all categories. | I9: 1) In app/products/page.tsx add generateMetadata({ searchParams }) that reads ?category=, looks up the category name and returns title: category ? <Suggested Title> : 'Buy RFID Readers, Tags & Antennas Online'. 2) Also return a matching meta description (use the category description) and canonical /products?category=<slug>. 3) Deploy and check page source for each category URL. | J9: RFID Laundry Tags | K9: =J9&" | Virtualsphere" -> RFID Laundry Tags | Virtualsphere | L9: =IF(K9="","",LEN(K9)) -> 33 | M9: Open
A10: T009 | B10: High | C10: Category | D10: RFID UHF Inlay | E10: https://indiarfidshop.com/products?category=rfid-uhf-inlay | F10: Duplicate title across category pages | G10: Products | Virtualsphere | H10: All 13 category pages share the title 'Products | Virtualsphere' (and the same meta description). Google treats them as duplicates and none ranks for 'RFID UHF Inlay'. Verified live on handheld-reader and raid-tags; same template for all categories. | I10: 1) In app/products/page.tsx add generateMetadata({ searchParams }) that reads ?category=, looks up the category name and returns title: category ? <Suggested Title> : 'Buy RFID Readers, Tags & Antennas Online'. 2) Also return a matching meta description (use the category description) and canonical /products?category=<slug>. 3) Deploy and check page source for each category URL. | J10: UHF RFID Inlays – Dry & Wet | K10: =J10&" | Virtualsphere" -> UHF RFID Inlays – Dry & Wet | Virtualsphere | L10: =IF(K10="","",LEN(K10)) -> 43 | M10: Open
A11: T010 | B11: High | C11: Category | D11: UHF RFID Tags | E11: https://indiarfidshop.com/products?category=uhf-rfid-tags | F11: Duplicate title across category pages | G11: Products | Virtualsphere | H11: All 13 category pages share the title 'Products | Virtualsphere' (and the same meta description). Google treats them as duplicates and none ranks for 'UHF RFID Tags'. Verified live on handheld-reader and raid-tags; same template for all categories. | I11: 1) In app/products/page.tsx add generateMetadata({ searchParams }) that reads ?category=, looks up the category name and returns title: category ? <Suggested Title> : 'Buy RFID Readers, Tags & Antennas Online'. 2) Also return a matching meta description (use the category description) and canonical /products?category=<slug>. 3) Deploy and check page source for each category URL. | J11: UHF RFID ABS Hard Tags | K11: =J11&" | Virtualsphere" -> UHF RFID ABS Hard Tags | Virtualsphere | L11: =IF(K11="","",LEN(K11)) -> 38 | M11: Open
A12: T011 | B12: High | C12: Category | D12: RFID UHF Antenna | E12: https://indiarfidshop.com/products?category=rfid-uhf-antenna | F12: Duplicate title across category pages | G12: Products | Virtualsphere | H12: All 13 category pages share the title 'Products | Virtualsphere' (and the same meta description). Google treats them as duplicates and none ranks for 'RFID UHF Antenna'. Verified live on handheld-reader and raid-tags; same template for all categories. | I12: 1) In app/products/page.tsx add generateMetadata({ searchParams }) that reads ?category=, looks up the category name and returns title: category ? <Suggested Title> : 'Buy RFID Readers, Tags & Antennas Online'. 2) Also return a matching meta description (use the category description) and canonical /products?category=<slug>. 3) Deploy and check page source for each category URL. | J12: UHF RFID Antennas | K12: =J12&" | Virtualsphere" -> UHF RFID Antennas | Virtualsphere | L12: =IF(K12="","",LEN(K12)) -> 33 | M12: Open
A13: T012 | B13: High | C13: Category | D13: RFID Handheld Reader | E13: https://indiarfidshop.com/products?category=handheld-reader | F13: Duplicate title across category pages | G13: Products | Virtualsphere | H13: All 13 category pages share the title 'Products | Virtualsphere' (and the same meta description). Google treats them as duplicates and none ranks for 'RFID Handheld Reader'. Verified live on handheld-reader and raid-tags; same template for all categories. | I13: 1) In app/products/page.tsx add generateMetadata({ searchParams }) that reads ?category=, looks up the category name and returns title: category ? <Suggested Title> : 'Buy RFID Readers, Tags & Antennas Online'. 2) Also return a matching meta description (use the category description) and canonical /products?category=<slug>. 3) Deploy and check page source for each category URL. | J13: UHF RFID Handheld Readers | K13: =J13&" | Virtualsphere" -> UHF RFID Handheld Readers | Virtualsphere | L13: =IF(K13="","",LEN(K13)) -> 41 | M13: Open
A14: T013 | B14: High | C14: Category | D14: UHF Desktop Reader | E14: https://indiarfidshop.com/products?category=uhf-desktop-reader | F14: Duplicate title across category pages | G14: Products | Virtualsphere | H14: All 13 category pages share the title 'Products | Virtualsphere' (and the same meta description). Google treats them as duplicates and none ranks for 'UHF Desktop Reader'. Verified live on handheld-reader and raid-tags; same template for all categories. | I14: 1) In app/products/page.tsx add generateMetadata({ searchParams }) that reads ?category=, looks up the category name and returns title: category ? <Suggested Title> : 'Buy RFID Readers, Tags & Antennas Online'. 2) Also return a matching meta description (use the category description) and canonical /products?category=<slug>. 3) Deploy and check page source for each category URL. | J14: UHF RFID Desktop Readers & Writers | K14: =J14&" | Virtualsphere" -> UHF RFID Desktop Readers & Writers | Virtualsphere | L14: =IF(K14="","",LEN(K14)) -> 50 | M14: Open
A15: T014 | B15: High | C15: Category | D15: HF RFID Reader | E15: https://indiarfidshop.com/products?category=hf-rfid-desktop-reader | F15: Duplicate title across category pages | G15: Products | Virtualsphere | H15: All 13 category pages share the title 'Products | Virtualsphere' (and the same meta description). Google treats them as duplicates and none ranks for 'HF RFID Reader'. Verified live on handheld-reader and raid-tags; same template for all categories. | I15: 1) In app/products/page.tsx add generateMetadata({ searchParams }) that reads ?category=, looks up the category name and returns title: category ? <Suggested Title> : 'Buy RFID Readers, Tags & Antennas Online'. 2) Also return a matching meta description (use the category description) and canonical /products?category=<slug>. 3) Deploy and check page source for each category URL. | J15: HF 13.56 MHz RFID Readers | K15: =J15&" | Virtualsphere" -> HF 13.56 MHz RFID Readers | Virtualsphere | L15: =IF(K15="","",LEN(K15)) -> 41 | M15: Open
... A34: T033 | B34: High | C34: Product | D34: UDR 102 | E34: https://indiarfidshop.com/products/udr-102 | F34: Model number missing from title | G34: RFID Desktop Reader | RFID Reader & Writer | 3-5 Mtrs range | Virtualsphere | H34: Title 'RFID Desktop Reader | RFID Reader & Writer | 3-5 Mtrs range' never mentions 'UDR 102'. Also repeats 'RFID Reader' and is too long. | I34: 1) In the admin panel, put the model number first: use the Suggested Title. 2) Buyers search by model (e.g. 'UDR 102'); the current title doesn't contain it. 3) Verify final title ≤ 60 characters. | J34: UDR 102 UHF RFID Desktop Reader & Writer | K34: =J34&" | Virtualsphere" -> UDR 102 UHF RFID Desktop Reader & Writer | Virtualsphere | L34: =IF(K34="","",LEN(K34)) -> 56 | M34: Open
A35: T034 | B35: High | C35: Sitewide | D35: All pages | E35: All pages | F35: Canonical tag missing | H35: No <link rel="canonical"> or og:url found on any page checked. Risk of duplicate URLs (case variants, ?sort=, ?search=) splitting ranking. | I35: 1) In app/layout.tsx set metadataBase: new URL('https://indiarfidshop.com'). 2) In each page's metadata add alternates: { canonical: '<path>' } (products: /products/<db slug>; categories: /products?category=<slug>). 3) Do NOT set a fixed canonical in the layout. 4) Verify with URL Inspection → 'User-declared canonical'. | M35: Open
A36: T035 | B36: Medium | C36: Main | D36: Products | E36: https://indiarfidshop.com/products | F36: Generic title – no keywords | G36: Products | Virtualsphere | H36: 'Products' tells Google nothing about what you sell. | I36: 1) Set a page-specific metadata title (Suggested Title) in this page's page.tsx. 2) Include what the page offers + a keyword (RFID readers, tags, India). 3) Deploy and verify in page source. | J36: Buy RFID Readers, Tags & Antennas Online | K36: =J36&" | Virtualsphere" -> Buy RFID Readers, Tags & Antennas Online | Virtualsphere | L36: =IF(K36="","",LEN(K36)) -> 56 | M36: Open
A37: T036 | B37: Medium | C37: Main | D37: Privacy Policy | E37: https://indiarfidshop.com/privacy | F37: Duplicate brand in title | G37: Privacy Policy - Virtualsphere | Virtualsphere | H37: 'Privacy Policy - Virtualsphere | Virtualsphere' – brand twice. | I37: 1) Set this page's metadata title to the Suggested Title only (no brand) – the layout template adds ' | Virtualsphere'. 2) For the homepage use title: { absolute: '<full title>' } so the template is not added twice. 3) Deploy and confirm the brand appears once in page source. | J37: Privacy Policy | K37: =J37&" | Virtualsphere" -> Privacy Policy | Virtualsphere | L37: =IF(K37="","",LEN(K37)) -> 30 | M37: Open
A38: T037 | B38: Medium | C38: Main | D38: Terms & Conditions | E38: https://indiarfidshop.com/terms | F38: Duplicate brand in title | G38: Terms & Conditions - Virtualsphere | Virtualsphere | H38: 'Terms & Conditions - Virtualsphere | Virtualsphere' – brand twice. | I38: 1) Set this page's metadata title to the Suggested Title only (no brand) – the layout template adds ' | Virtualsphere'. 2) For the homepage use title: { absolute: '<full title>' } so the template is not added twice. 3) Deploy and confirm the brand appears once in page source. | J38: Terms & Conditions | K38: =J38&" | Virtualsphere" -> Terms & Conditions | Virtualsphere | L38: =IF(K38="","",LEN(K38)) -> 34 | M38: Open
A39: T038 | B39: Medium | C39: Category | D39: RFID Tags | E39: https://indiarfidshop.com/products?category=raid-tags | F39: Typo in category URL | G39: https://indiarfidshop.com/products?category=raid-tags | H39: Slug 'raid-tags' should be 'rfid-tags' – keyword in URL is misspelled. | I39: 1) Rename the category slug in admin (raid-tags → rfid-tags; rfid-laundary-tags → rfid-laundry-tags). 2) Add a 301 redirect from the old URL to the new URL (next.config.js redirects()). 3) Update all internal links and the sitemap.xml entry, then resubmit the sitemap in Search Console. | J39: https://indiarfidshop.com/products?category=rfid-tags | M39: Open
A40: T039 | B40: Medium | C40: Category | D40: RFID Laundry Tags | E40: https://indiarfidshop.com/products?category=rfid-laundary-tags | F40: Typo in category URL | G40: https://indiarfidshop.com/products?category=rfid-laundary-tags | H40: Slug 'laundary' should be 'laundry' (also in the 'RFID Laundary Tags' category name). | I40: 1) Rename the category slug in admin (raid-tags → rfid-tags; rfid-laundary-tags → rfid-laundry-tags). 2) Add a 301 redirect from the old URL to the new URL (next.config.js redirects()). 3) Update all internal links and the sitemap.xml entry, then resubmit the sitemap in Search Console. | J40: https://indiarfidshop.com/products?category=rfid-laundry-tags | M40: Open
A41: T040 | B41: Medium | C41: Product | D41: UDR-W101 | E41: https://indiarfidshop.com/products/udr-w101-uhf-rfid-desktop-reader-writer | F41: H1 contains '|' / brand text | G41: (see Problem Details) | H41: The visible H1 heading includes pipe text such as '| Virtualsphere' – headings should be the clean product name. | I41: 1) In the admin panel, set the product display name (H1) to the clean product name without '| Virtualsphere' or other pipe text. 2) If H1 and SEO title share one field, add a separate 'SEO Title' field so H1 stays clean. 3) Deploy and check that the page has exactly one H1. | J41: UDR-W101 RFID Desktop Reader & Writer | M41: Open
A42: T041 | B42: Medium | C42: Product | D42: UDT9R Jewellery Tray Reader | E42: https://indiarfidshop.com/products/udt9r-rfid-jewellery-tray-reader | F42: H1 contains '|' / brand text | G42: (see Problem Details) | H42: The visible H1 heading includes pipe text such as '| Virtualsphere' – headings should be the clean product name. | I42: 1) In the admin panel, set the product display name (H1) to the clean product name without '| Virtualsphere' or other pipe text. 2) If H1 and SEO title share one field, add a separate 'SEO Title' field so H1 stays clean. 3) Deploy and check that the page has exactly one H1. | J42: UDT9R RFID Jewellery Tray Reader | M42: Open
A43: T042 | B43: Medium | C43: Product | D43: UHR2 | E43: https://indiarfidshop.com/products/uhr2-uhf-rfid-handheld-reader | F43: H1 contains '|' / brand text | G43: (see Problem Details) | H43: The visible H1 heading includes pipe text such as '| Virtualsphere' – headings should be the clean product name. | I43: 1) In the admin panel, set the product display name (H1) to the clean product name without '| Virtualsphere' or other pipe text. 2) If H1 and SEO title share one field, add a separate 'SEO Title' field so H1 stays clean. 3) Deploy and check that the page has exactly one H1. | J43: UHR2 UHF RFID Handheld Reader | M43: Open
A44: T043 | B44: Medium | C44: Product | D44: VSL-F2 | E44: https://indiarfidshop.com/products/vsl-f2-uhf-rfid-4-port-reader | F44: H1 contains '|' / brand text | G44: (see Problem Details) | H44: The visible H1 heading includes pipe text such as '| Virtualsphere' – headings should be the clean product name. | I44: 1) In the admin panel, set the product display name (H1) to the clean product name without '| Virtualsphere' or other pipe text. 2) If H1 and SEO title share one field, add a separate 'SEO Title' field so H1 stays clean. 3) Deploy and check that the page has exactly one H1. | J44: VSL-F2 UHF RFID 4 Port Reader – Impinj E710 | M44: Open
A45: T044 | B45: Medium | C45: Product | D45: UHR 72 | E45: https://indiarfidshop.com/products/uhr-72 | F45: Weak meta description | G45: (see Problem Details) | H45: Meta description = title copy only ('RFID Handheld Reader | UHR 72'). | I45: 1) In the admin panel, replace the meta description with the Suggested Value (140–160 characters). 2) Include model, 2–3 key specs and the use case; don't repeat the title. 3) Deploy and verify <meta name="description"> in page source. | J45: Buy the UHR 72 UHF RFID handheld reader – EPC Gen2 / ISO 18000-6C with Gen2v2 authentication. Ideal for inventory, warehouse and asset tracking. | M45: Open
A46: T045 | B46: Medium | C46: Product | D46: UDM9R | E46: https://indiarfidshop.com/products/udm9r-Integrated-reader | F46: Weak meta description | G46: (see Problem Details) | H46: Too short (≈75 chars), no specs. | I46: 1) In the admin panel, replace the meta description with the Suggested Value (140–160 characters). 2) Include model, 2–3 key specs and the use case; don't repeat the title. 3) Deploy and verify <meta name="description"> in page source. | J46: UDM9R long range integrated UHF RFID reader with Impinj E310, 9dBi antenna, up to 15 m range, IP68, RS232, RJ45, Wiegand & GPIO interfaces. | M46: Open
A47: T046 | B47: Medium | C47: Product | D47: UDM12R | E47: https://indiarfidshop.com/products/udm12r-uhf-Integrated-reader | F47: Weak meta description | G47: (see Problem Details) | H47: Too short (≈76 chars), no specs. | I47: 1) In the admin panel, replace the meta description with the Suggested Value (140–160 characters). 2) Include model, 2–3 key specs and the use case; don't repeat the title. 3) Deploy and verify <meta name="description"> in page source. | J47: UDM12R Impinj-based integrated UHF RFID reader, EPC Gen2 V2, read range up to 20 m, RS232, RJ45 & GPIO – for access control, logistics & assets. | M47: Open
A48: T047 | B48: Medium | C48: Product | D48: UDR 107 | E48: https://indiarfidshop.com/products/udr-107 | F48: Weak meta description | G48: (see Problem Details) | H48: Too short and unclear ('10-15mtrs Reader Long range desktop operating reader'). | I48: 1) In the admin panel, replace the meta description with the Suggested Value (140–160 characters). 2) Include model, 2–3 key specs and the use case; don't repeat the title. 3) Deploy and verify <meta name="description"> in page source. | J48: UDR 107 long range UHF RFID desktop reader with 10–15 m read range for gates, counters and inventory points. Easy integration with your software. | M48: Open
A49: T048 | B49: Medium | C49: Product | D49: HRP 70 Pendrive Reader | E49: https://indiarfidshop.com/products/hrp-70-pendrive-reader | F49: Weak meta description | G49: (see Problem Details) | H49: Keyword list, not a sentence ('RFID Pendrive Reader | 13.56Mhz Reader | Portable Reader'). | I49: 1) In the admin panel, replace the meta description with the Suggested Value (140–160 characters). 2) Include model, 2–3 key specs and the use case; don't repeat the title. 3) Deploy and verify <meta name="description"> in page source. | J49: HRP 70 driver-free 13.56MHz HF RFID USB pendrive reader, up to 80 mm range, IP65. Plug-and-play for access cards, attendance and NFC tags. | M49: Open
A50: T049 | B50: Medium | C50: Product | D50: UDR 102 | E50: https://indiarfidshop.com/products/udr-102 | F50: Weak meta description | G50: (see Problem Details) | H50: Too long (≈280 chars) – Google cuts it at ~160. | I50: 1) In the admin panel, replace the meta description with the Suggested Value (140–160 characters). 2) Include model, 2–3 key specs and the use case; don't repeat the title. 3) Deploy and verify <meta name="description"> in page source. | J50: UDR 102 UHF RFID desktop reader & writer with 3–5 m range for POS, registration and inventory. Works with Windows, iOS, Android and Linux. | M50: Open
A51: T050 | B51: Medium | C51: Sitewide | D51: All main pages + categories | E51: All main pages + categories | F51: Generic og:title (social share title) | H51: og:title is 'Virtualsphere — Enterprise RFID Solutions' on home, products, categories, about, contact, privacy, terms and category pages – WhatsApp/LinkedIn shares all look the same. | I51: 1) In each page's metadata set openGraph: { title: <same as page title>, url: <path> }. 2) Deploy and test a link in WhatsApp or LinkedIn Post Inspector. | M51: Open
A52: T051 | B52: Medium | C52: Sitewide | D52: All product pages | E52: All product pages | F52: Generic twitter:title / twitter:description | H52: Seen on UDM9R: twitter:title = 'Virtualsphere — Enterprise RFID Solutions' instead of the product name. | I52: 1) In product generateMetadata add twitter: { title: <product title>, description: <meta description>, images: [<product image>] }. 2) Deploy and verify in page source. | M52: Open
A53: T052 | B53: Medium | C53: Main | D53: Privacy Policy | E53: https://indiarfidshop.com/privacy | F53: Page content not visible to crawlers | H53: Privacy page text was not found in the server HTML (only header/footer). | I53: 1) Render the policy text on the server (no client-only fetch) or add it as static content. 2) Verify with URL Inspection → View crawled page. | M53: Open
A54: T053 | B54: Medium | C54: Main | D54: Terms & Conditions | E54: https://indiarfidshop.com/terms | F54: Page content not visible to crawlers | H54: Terms page text was not found in the server HTML (only header/footer). | I54: 1) Render the terms text on the server (no client-only fetch) or add it as static content. 2) Verify with URL Inspection → View crawled page. | M54: Open
A55: T054 | B55: Low | C55: Main | D55: Categories | E55: https://indiarfidshop.com/categories | F55: Generic title – no keywords | G55: Categories | Virtualsphere | H55: 'Categories' has no search value. | I55: 1) Set a page-specific metadata title (Suggested Title) in this page's page.tsx. 2) Include what the page offers + a keyword (RFID readers, tags, India). 3) Deploy and verify in page source. | J55: RFID Product Categories | K55: =J55&" | Virtualsphere" -> RFID Product Categories | Virtualsphere | L55: =IF(K55="","",LEN(K55)) -> 39 | M55: Open
A56: T055 | B56: Low | C56: Main | D56: About | E56: https://indiarfidshop.com/about | F56: Generic title – no keywords | G56: About Us | Virtualsphere | H56: Could carry brand + 'RFID manufacturer in India' for brand searches. | I56: 1) Set a page-specific metadata title (Suggested Title) in this page's page.tsx. 2) Include what the page offers + a keyword (RFID readers, tags, India). 3) Deploy and verify in page source. | J56: About Us – RFID Manufacturer in India | K56: =J56&" | Virtualsphere" -> About Us – RFID Manufacturer in India | Virtualsphere | L56: =IF(K56="","",LEN(K56)) -> 53 | M56: Open
A57: T056 | B57: Low | C57: Main | D57: Contact | E57: https://indiarfidshop.com/contact | F57: Generic title – no keywords | G57: Contact | Virtualsphere | H57: Generic; add intent words people search (quote, support). | I57: 1) Set a page-specific metadata title (Suggested Title) in this page's page.tsx. 2) Include what the page offers + a keyword (RFID readers, tags, India). 3) Deploy and verify in page source. | J57: Contact Us – RFID Quotes & Support | K57: =J57&" | Virtualsphere" -> Contact Us – RFID Quotes & Support | Virtualsphere | L57: =IF(K57="","",LEN(K57)) -> 50 | M57: Open
A58: T057 | B58: Low | C58: Main | D58: Contact | E58: https://indiarfidshop.com/contact | F58: H1 does not match page | G58: (see Problem Details) | H58: H1 found on contact page: 'India RFID shop — RFID readers, tags, wristbands manufacturer & supplier' – not about contacting you. | I58: 1) In the admin panel, set the contact page heading (H1) to the clean product name without '| Virtualsphere' or other pipe text. 2) If H1 and SEO title share one field, add a separate 'SEO Title' field so H1 stays clean. 3) Deploy and check that the page has exactly one H1. | J58: Contact Virtualsphere | M58: Open
...

Sheet All Pages
A1: Page Type | B1: Page Name | C1: Page URL | D1: Current Title | E1: Length | F1: 'Virtualsphere' count | G1: Length Check | H1: Duplicate Check | I1: Issues Found | J1: Open Issues | K1: Overall
A2: Home | B2: Homepage | C2: https://indiarfidshop.com/ | D2: Virtualsphere — Enterprise RFID Solutions | Virtualsphere | E2: =LEN(D2) -> 57 | F2: =(LEN(D2)-LEN(SUBSTITUTE(D2,"Virtualsphere","")))/LEN("Virtualsphere") -> 2 | G2: =IF(E2>60,"Too long",IF(E2<30,"Too short","OK")) -> OK | H2: =IF(COUNTIF($D$2:$D$50,D2)>1,"Duplicate","Unique") -> Unique | I2: =COUNTIF(Issues!$E$2:$E$74,C2) -> 2 | J2: =COUNTIFS(Issues!$E$2:$E$74,C2,Issues!$M$2:$M$74,"<>Fixed",Issues!$M$2:$M$74,"<>Verified") -> 2 | K2: =IF(J2>0,"Needs fix","OK") -> Needs fix
A3: Main | B3: Products | C3: https://indiarfidshop.com/products | D3: Products | Virtualsphere | E3: =LEN(D3) -> 24 | F3: =(LEN(D3)-LEN(SUBSTITUTE(D3,"Virtualsphere","")))/LEN("Virtualsphere") -> 1 | G3: =IF(E3>60,"Too long",IF(E3<30,"Too short","OK")) -> Too short | H3: =IF(COUNTIF($D$2:$D$50,D3)>1,"Duplicate","Unique") -> Duplicate | I3: =COUNTIF(Issues!$E$2:$E$74,C3) -> 1 | J3: =COUNTIFS(Issues!$E$2:$E$74,C3,Issues!$M$2:$M$74,"<>Fixed",Issues!$M$2:$M$74,"<>Verified") -> 1 | K3: =IF(J3>0,"Needs fix","OK") -> Needs fix
A4: Main | B4: Categories | C4: https://indiarfidshop.com/categories | D4: Categories | Virtualsphere | E4: =LEN(D4) -> 26 | F4: =(LEN(D4)-LEN(SUBSTITUTE(D4,"Virtualsphere","")))/LEN("Virtualsphere") -> 1 | G4: =IF(E4>60,"Too long",IF(E4<30,"Too short","OK")) -> Too short | H4: =IF(COUNTIF($D$2:$D$50,D4)>1,"Duplicate","Unique") -> Unique | I4: =COUNTIF(Issues!$E$2:$E$74,C4) -> 1 | J4: =COUNTIFS(Issues!$E$2:$E$74,C4,Issues!$M$2:$M$74,"<>Fixed",Issues!$M$2:$M$74,"<>Verified") -> 1 | K4: =IF(J4>0,"Needs fix","OK") -> Needs fix
A5: Main | B5: About | C5: https://indiarfidshop.com/about | D5: About Us | Virtualsphere | E5: =LEN(D5) -> 24 | F5: =(LEN(D5)-LEN(SUBSTITUTE(D5,"Virtualsphere","")))/LEN("Virtualsphere") -> 1 | G5: =IF(E5>60,"Too long",IF(E5<30,"Too short","OK")) -> Too short | H5: =IF(COUNTIF($D$2:$D$50,D5)>1,"Duplicate","Unique") -> Unique | I5: =COUNTIF(Issues!$E$2:$E$74,C5) -> 1 | J5: =COUNTIFS(Issues!$E$2:$E$74,C5,Issues!$M$2:$M$74,"<>Fixed",Issues!$M$2:$M$74,"<>Verified") -> 1 | K5: =IF(J5>0,"Needs fix","OK") -> Needs fix
A6: Main | B6: Contact | C6: https://indiarfidshop.com/contact | D6: Contact | Virtualsphere | E6: =LEN(D6) -> 23 | F6: =(LEN(D6)-LEN(SUBSTITUTE(D6,"Virtualsphere","")))/LEN("Virtualsphere") -> 1 | G6: =IF(E6>60,"Too long",IF(E6<30,"Too short","OK")) -> Too short | H6: =IF(COUNTIF($D$2:$D$50,D6)>1,"Duplicate","Unique") -> Unique | I6: =COUNTIF(Issues!$E$2:$E$74,C6) -> 2 | J6: =COUNTIFS(Issues!$E$2:$E$74,C6,Issues!$M$2:$M$74,"<>Fixed",Issues!$M$2:$M$74,"<>Verified") -> 2 | K6: =IF(J6>0,"Needs fix","OK") -> Needs fix
A7: Main | B7: Privacy Policy | C7: https://indiarfidshop.com/privacy | D7: Privacy Policy - Virtualsphere | Virtualsphere | E7: =LEN(D7) -> 46 | F7: =(LEN(D7)-LEN(SUBSTITUTE(D7,"Virtualsphere","")))/LEN("Virtualsphere") -> 2 | G7: =IF(E7>60,"Too long",IF(E7<30,"Too short","OK")) -> OK | H7: =IF(COUNTIF($D$2:$D$50,D7)>1,"Duplicate","Unique") -> Unique | I7: =COUNTIF(Issues!$E$2:$E$74,C7) -> 2 | J7: =COUNTIFS(Issues!$E$2:$E$74,C7,Issues!$M$2:$M$74,"<>Fixed",Issues!$M$2:$M$74,"<>Verified") -> 2 | K7: =IF(J7>0,"Needs fix","OK") -> Needs fix
A8: Main | B8: Terms & Conditions | C8: https://indiarfidshop.com/terms | D8: Terms & Conditions - Virtualsphere | Virtualsphere | E8: =LEN(D8) -> 50 | F8: =(LEN(D8)-LEN(SUBSTITUTE(D8,"Virtualsphere","")))/LEN("Virtualsphere") -> 2 | G8: =IF(E8>60,"Too long",IF(E8<30,"Too short","OK")) -> OK | H8: =IF(COUNTIF($D$2:$D$50,D8)>1,"Duplicate","Unique") -> Unique | I8: =COUNTIF(Issues!$E$2:$E$74,C8) -> 2 | J8: =COUNTIFS(Issues!$E$2:$E$74,C8,Issues!$M$2:$M$74,"<>Fixed",Issues!$M$2:$M$74,"<>Verified") -> 2 | K8: =IF(J8>0,"Needs fix","OK") -> Needs fix
A9: Category | B9: Barcode Printers | C9: https://indiarfidshop.com/products?category=barcode-printers | D9: Products | Virtualsphere | E9: =LEN(D9) -> 24 | F9: =(LEN(D9)-LEN(SUBSTITUTE(D9,"Virtualsphere","")))/LEN("Virtualsphere") -> 1 | G9: =IF(E9>60,"Too long",IF(E9<30,"Too short","OK")) -> Too short | H9: =IF(COUNTIF($D$2:$D$50,D9)>1,"Duplicate","Unique") -> Duplicate | I9: =COUNTIF(Issues!$E$2:$E$74,C9) -> 1 | J9: =COUNTIFS(Issues!$E$2:$E$74,C9,Issues!$M$2:$M$74,"<>Fixed",Issues!$M$2:$M$74,"<>Verified") -> 1 | K9: =IF(J9>0,"Needs fix","OK") -> Needs fix
A10: Category | B10: UHF Integrated Reader | C10: https://indiarfidshop.com/products?category=integrated-reader | D10: Products | Virtualsphere | E10: =LEN(D10) -> 24 | F10: =(LEN(D10)-LEN(SUBSTITUTE(D10,"Virtualsphere","")))/LEN("Virtualsphere") -> 1 | G10: =IF(E10>60,"Too long",IF(E10<30,"Too short","OK")) -> Too short | H10: =IF(COUNTIF($D$2:$D$50,D10)>1,"Duplicate","Unique") -> Duplicate | I10: =COUNTIF(Issues!$E$2:$E$74,C10) -> 1 | J10: =COUNTIFS(Issues!$E$2:$E$74,C10,Issues!$M$2:$M$74,"<>Fixed",Issues!$M$2:$M$74,"<>Verified") -> 1 | K10: =IF(J10>0,"Needs fix","OK") -> Needs fix
A11: Category | B11: Four Port UHF Reader | C11: https://indiarfidshop.com/products?category=four-port-reader | D11: Products | Virtualsphere | E11: =LEN(D11) -> 24 | F11: =(LEN(D11)-LEN(SUBSTITUTE(D11,"Virtualsphere","")))/LEN("Virtualsphere") -> 1 | G11: =IF(E11>60,"Too long",IF(E11<30,"Too short","OK")) -> Too short | H11: =IF(COUNTIF($D$2:$D$50,D11)>1,"Duplicate","Unique") -> Duplicate | I11: =COUNTIF(Issues!$E$2:$E$74,C11) -> 1 | J11: =COUNTIFS(Issues!$E$2:$E$74,C11,Issues!$M$2:$M$74,"<>Fixed",Issues!$M$2:$M$74,"<>Verified") -> 1 | K11: =IF(J11>0,"Needs fix","OK") -> Needs fix
A12: Category | B12: RFID Tags | C12: https://indiarfidshop.com/products?category=raid-tags | D12: Products | Virtualsphere | E12: =LEN(D12) -> 24 | F12: =(LEN(D12)-LEN(SUBSTITUTE(D12,"Virtualsphere","")))/LEN("Virtualsphere") -> 1 | G12: =IF(E12>60,"Too long",IF(E12<30,"Too short","OK")) -> Too short | H12: =IF(COUNTIF($D$2:$D$50,D12)>1,"Duplicate","Unique") -> Duplicate | I12: =COUNTIF(Issues!$E$2:$E$74,C12) -> 2 | J12: =COUNTIFS(Issues!$E$2:$E$74,C12,Issues!$M$2:$M$74,"<>Fixed",Issues!$M$2:$M$74,"<>Verified") -> 2 | K12: =IF(J12>0,"Needs fix","OK") -> Needs fix
A13: Category | B13: RFID UHF Labels | C13: https://indiarfidshop.com/products?category=Rfid-uhf-label-tags | D13: Products | Virtualsphere | E13: =LEN(D13) -> 24 | F13: =(LEN(D13)-LEN(SUBSTITUTE(D13,"Virtualsphere","")))/LEN("Virtualsphere") -> 1 | G13: =IF(E13>60,"Too long",IF(E13<30,"Too short","OK")) -> Too short | H13: =IF(COUNTIF($D$2:$D$50,D13)>1,"Duplicate","Unique") -> Duplicate | I13: =COUNTIF(Issues!$E$2:$E$74,C13) -> 1 | J13: =COUNTIFS(Issues!$E$2:$E$74,C13,Issues!$M$2:$M$74,"<>Fixed",Issues!$M$2:$M$74,"<>Verified") -> 1 | K13: =IF(J13>0,"Needs fix","OK") -> Needs fix
... A50: Product | B50: Dogbone UHF Inlays | C50: https://indiarfidshop.com/products/dogbone-rfid-uhf-inlays | D50: Dogbone RFID UHF Inlays | Impinj M730 Tag, 15 m Range | Virtualsphere | E50: =LEN(D50) -> 69 | F50: =(LEN(D50)-LEN(SUBSTITUTE(D50,"Virtualsphere","")))/LEN("Virtualsphere") -> 1 | G50: =IF(E50>60,"Too long",IF(E50<30,"Too short","OK")) -> Too long | H50: =IF(COUNTIF($D$2:$D$50,D50)>1,"Duplicate","Unique") -> Unique | I50: =COUNTIF(Issues!$E$2:$E$74,C50) -> 1 | J50: =COUNTIFS(Issues!$E$2:$E$74,C50,Issues!$M$2:$M$74,"<>Fixed",Issues!$M$2:$M$74,"<>Verified") -> 1 | K50: =IF(J50>0,"Needs fix","OK") -> Needs fix

Sheet Code Fixes
A1: Fix | B1: Where | C1: Code / Steps | D1: Fixes Problems
A2: 1. Remove duplicate brand | B2: app/products/[slug]/page.tsx | C2: const clean = (t: string) => t.replace(/\s*\|\s*Virtualsphere\s*$/i, ""); export async function generateMetadata({ params }) { const { slug } = await params; const p = await getProduct(slug); const title = clean(p.seoTitle || p.name); return { title, // layout template adds ' | Virtualsphere' description: p.metaDescription, alternates: { canonical: `/products/${p.slug}` }, openGraph: { title, url: `/products/${p.slug}`, images: [p.image] }, twitter: { title, description: p.metaDescription, images: [p.image] }, }; } | D2: Duplicate brand in title; Generic twitter:title; Canonical tag missing
A3: 2. Layout title template + base URL | B3: app/layout.tsx | C3: export const metadata: Metadata = { metadataBase: new URL("https://indiarfidshop.com"), title: { default: "RFID Readers, Tags & Antennas in India | Virtualsphere", template: "%s | Virtualsphere", }, }; // Do NOT put alternates.canonical here. | D3: Duplicate brand in title; Canonical tag missing
A4: 3. Homepage title | B4: app/page.tsx | C4: export const metadata = { title: { absolute: "RFID Readers, Tags & Antennas in India | Virtualsphere" }, alternates: { canonical: "/" }, openGraph: { url: "/" }, }; | D4: Homepage duplicate brand; Generic title
A5: 4. Unique category titles | B5: app/products/page.tsx | C5: export async function generateMetadata({ searchParams }) { const { category } = await searchParams; if (!category) return { title: "Buy RFID Readers, Tags & Antennas Online", alternates: { canonical: "/products" }, }; const c = await getCategory(category); const path = `/products?category=${encodeURIComponent(c.slug)}`; return { title: c.seoTitle || c.name, // see Issues sheet for suggested titles description: c.description?.slice(0, 160), alternates: { canonical: path }, openGraph: { title: c.seoTitle || c.name, url: path }, }; } | D5: Duplicate title across category pages; Generic /products title
A6: 5. Static pages | B6: app/about, contact, privacy, terms, categories → page.tsx | C6: export const metadata = { title: "About Us – RFID Manufacturer in India", // no brand – template adds it alternates: { canonical: "/about" }, openGraph: { url: "/about" }, }; | D6: Generic titles; Duplicate brand on privacy/terms; Generic og:title
A7: 6. Category slug redirects | B7: next.config.js | C7: async redirects() { return [ { source: '/products', has: [{ type: 'query', key: 'category', value: 'raid-tags' }], destination: '/products?category=rfid-tags', permanent: true }, { source: '/products', has: [{ type: 'query', key: 'category', value: 'rfid-laundary-tags' }], destination: '/products?category=rfid-laundry-tags', permanent: true }, ]; } // Then rename slugs in admin and update sitemap.xml | D7: Typo in category URL
A8: 7. Verify after deploy | B8: Browser / Search Console | C8: 1) View page source (Ctrl+U) → check <title>, <meta name="description">, <link rel="canonical">. 2) Search Console → URL Inspection → Test live URL → View tested page. 3) Set the row Status to 'Fixed', then 'Verified' after Google recrawls. 4) Re-run: the All Pages sheet flags titles over 60 chars / duplicates once you paste new titles in column D. | D8: All
